<?xml version="1.0" encoding="utf-8"?>
<!-- This URDF was automatically created by SolidWorks to URDF Exporter! Originally created by Stephen Brawner (brawner@gmail.com) 
     Commit Version: 1.6.0-1-g15f4949  Build Version: 1.6.7594.29634
     For more information, please see http://wiki.ros.org/sw_urdf_exporter -->
<robot
  name="DRV90ASS.SLDASM">
  <link
    name="base_link">
    <inertial>
      <origin
        xyz="-0.0238384941898682 -0.113302007869029 5.58415524585643E-06"
        rpy="0 0 0" />
      <mass
        value="8.21721836139231" />
      <inertia
        ixx="0.0508660547767537"
        ixy="0.0035598519099378"
        ixz="0.000108158619401827"
        iyy="0.0514755716480075"
        iyz="-5.07007251702943E-05"
        izz="0.0656830666681247" />
    </inertial>
    <visual>
      <origin
        xyz="0 0 0"
        rpy="0 0 0" />
      <geometry>
        <mesh
          filename="package://DRV90ASS.SLDASM/meshes/Base_Link.STL" />
      </geometry>
      <material
        name="">
        <color
          rgba="0.792156862745098 0.819607843137255 0.933333333333333 1" />
      </material>
    </visual>
    <collision>
      <origin
        xyz="0 0 0"
        rpy="0 0 0" />
      <geometry>
        <mesh
          filename="package://DRV90ASS.SLDASM/meshes/Base_Link.STL" />
      </geometry>
    </collision>
  </link>
  <link
    name="Joint1_Link">
    <inertial>
      <origin
        xyz="-0.0078510155863701 0.000183330858657822 0.299286127055427"
        rpy="0 0 0" />
      <mass
        value="2.90434630675253" />
      <inertia
        ixx="0.0147072420657371"
        ixy="-0.000696046429323042"
        ixz="0.00146170434717375"
        iyy="0.0143759794358876"
        iyz="0.00358521200707209"
        izz="0.0112445108474454" />
    </inertial>
    <visual>
      <origin
        xyz="0 0 0"
        rpy="0 0 0" />
      <geometry>
        <mesh
          filename="package://DRV90ASS.SLDASM/meshes/Joint01_Link.STL" />
      </geometry>
      <material
        name="">
        <color
          rgba="0.792156862745098 0.819607843137255 0.933333333333333 1" />
      </material>
    </visual>
    <collision>
      <origin
        xyz="0 0 0"
        rpy="0 0 0" />
      <geometry>
        <mesh
          filename="package://DRV90ASS.SLDASM/meshes/Joint01_Link.STL" />
      </geometry>
    </collision>
  </link>
  <joint
    name="Joint01"
    type="revolute">
    <origin
      xyz="0 0 0"
      rpy="-1.5708 0 -3.1416" />
    <parent
      link="base_link" />
    <child
      link="Joint1_Link" />
    <axis
      xyz="0 0 1" />
    <limit
      lower="-2.9671"
      upper="2.9671"
      effort="500"
      velocity="6.4577" />
  </joint>
  <link
    name="Joint02_Link">
    <inertial>
      <origin
        xyz="-1.61352567426107E-05 0.190387178474749 -0.0115695258249138"
        rpy="0 0 0" />
      <mass
        value="8.50782819907349" />
      <inertia
        ixx="0.15319088594903"
        ixy="-0.0167758962420301"
        ixz="-0.00016843239004597"
        iyy="0.0218221768654065"
        iyz="0.00170921109658809"
        izz="0.154487750775029" />
    </inertial>
    <visual>
      <origin
        xyz="0 0 0"
        rpy="0 0 0" />
      <geometry>
        <mesh
          filename="package://DRV90ASS.SLDASM/meshes/Joint02_Link.STL" />
      </geometry>
      <material
        name="">
        <color
          rgba="0.792156862745098 0.819607843137255 0.933333333333333 1" />
      </material>
    </visual>
    <collision>
      <origin
        xyz="0 0 0"
        rpy="0 0 0" />
      <geometry>
        <mesh
          filename="package://DRV90ASS.SLDASM/meshes/Joint02_Link.STL" />
      </geometry>
    </collision>
  </link>
  <joint
    name="Joint02"
    type="revolute">
    <origin
      xyz="-0.025 0 0.374"
      rpy="1.5708 0 -1.5708" />
    <parent
      link="Joint1_Link" />
    <child
      link="Joint02_Link" />
    <axis
      xyz="1 0 0" />
    <limit
      lower="-1.8326"
      upper="2.3562"
      effort="500"
      velocity="4.5379" />
  </joint>
  <link
    name="Joint03_Link">
    <inertial>
      <origin
        xyz="0.0261468707125698 -0.03247720771821 2.95937572811065E-05"
        rpy="0 0 0" />
      <mass
        value="3.57362282514091" />
      <inertia
        ixx="0.0156200493902243"
        ixy="0.00246074621075575"
        ixz="-2.2992248884414E-07"
        iyy="0.00851925661257946"
        iyz="1.22803645754272E-06"
        izz="0.0164662271025182" />
    </inertial>
    <visual>
      <origin
        xyz="0 0 0"
        rpy="0 0 0" />
      <geometry>
        <mesh
          filename="package://DRV90ASS.SLDASM/meshes/Joint_03_Link.STL" />
      </geometry>
      <material
        name="">
        <color
          rgba="0.792156862745098 0.819607843137255 0.933333333333333 1" />
      </material>
    </visual>
    <collision>
      <origin
        xyz="0 0 0"
        rpy="0 0 0" />
      <geometry>
        <mesh
          filename="package://DRV90ASS.SLDASM/meshes/Joint_03_Link.STL" />
      </geometry>
    </collision>
  </link>
  <joint
    name="Joint03"
    type="revolute">
    <origin
      xyz="0 0.44 0"
      rpy="-1.5708 0 1.5708" />
    <parent
      link="Joint02_Link" />
    <child
      link="Joint03_Link" />
    <axis
      xyz="0 0 -1" />
    <limit
      lower="-3.5779"
      upper="1.0472"
      effort="500"
      velocity="7.1558" />
  </joint>
  <link
    name="Joint04_Link">
    <inertial>
      <origin
        xyz="-7.28198976077091E-05 -2.05089976967887E-06 0.0779319378963943"
        rpy="0 0 0" />
      <mass
        value="3.22944178208382" />
      <inertia
        ixx="0.00947041713488305"
        ixy="-1.80115148617832E-06"
        ixz="0.000419038670237326"
        iyy="0.00812006631086119"
        iyz="-4.3850484351728E-06"
        izz="0.00488083877755292" />
    </inertial>
    <visual>
      <origin
        xyz="0 0 0"
        rpy="0 0 0" />
      <geometry>
        <mesh
          filename="package://DRV90ASS.SLDASM/meshes/Joint_04_Link.STL" />
      </geometry>
      <material
        name="">
        <color
          rgba="0.752941176470588 0.752941176470588 0.752941176470588 1" />
      </material>
    </visual>
    <collision>
      <origin
        xyz="0 0 0"
        rpy="0 0 0" />
      <geometry>
        <mesh
          filename="package://DRV90ASS.SLDASM/meshes/Joint_04_Link.STL" />
      </geometry>
    </collision>
  </link>
  <joint
    name="Joint04"
    type="revolute">
    <origin
      xyz="0.04 -0.1945 0"
      rpy="1.5708 1.5708 0" />
    <parent
      link="Joint03_Link" />
    <child
      link="Joint04_Link" />
    <axis
      xyz="0 0 1" />
    <limit
      lower="-3.3161"
      upper="3.3161"
      effort="16.6"
      velocity="9.5993" />
  </joint>
  <link
    name="Joint05_Link">
    <inertial>
      <origin
        xyz="0.00679837786534578 -3.20592992727464E-05 0.0168252512927224"
        rpy="0 0 0" />
      <mass
        value="0.237062085522172" />
      <inertia
        ixx="0.000181246598160827"
        ixy="1.67414422444251E-07"
        ixz="1.21191081903164E-05"
        iyy="0.000179402627087052"
        iyz="-8.7648051091927E-09"
        izz="0.000147616832246219" />
    </inertial>
    <visual>
      <origin
        xyz="0 0 0"
        rpy="0 0 0" />
      <geometry>
        <mesh
          filename="package://DRV90ASS.SLDASM/meshes/Joint_05_Link.STL" />
      </geometry>
      <material
        name="">
        <color
          rgba="0.752941176470588 0.752941176470588 0.752941176470588 1" />
      </material>
    </visual>
    <collision>
      <origin
        xyz="0 0 0"
        rpy="0 0 0" />
      <geometry>
        <mesh
          filename="package://DRV90ASS.SLDASM/meshes/Joint_05_Link.STL" />
      </geometry>
    </collision>
  </link>
  <joint
    name="Joint05"
    type="revolute">
    <origin
      xyz="0 0 0.2405"
      rpy="0 0 0" />
    <parent
      link="Joint04_Link" />
    <child
      link="Joint05_Link" />
    <axis
      xyz="1 0 0" />
    <limit
      lower="-2.0944"
      upper="2.0944"
      effort="16.6"
      velocity="9.5993" />
  </joint>
  <link
    name="Joint06_Link">
    <inertial>
      <origin
        xyz="6.35206686190604E-05 0.000237153503421017 -0.00361576649514428"
        rpy="0 0 0" />
      <mass
        value="0.0383087175761794" />
      <inertia
        ixx="1.2091184287295E-05"
        ixy="4.2092006717223E-08"
        ixz="-2.52055131748701E-10"
        iyy="1.22454762819957E-05"
        iyz="-1.10050816513221E-08"
        izz="2.34988639337108E-05" />
    </inertial>
    <visual>
      <origin
        xyz="0 0 0"
        rpy="0 0 0" />
      <geometry>
        <mesh
          filename="package://DRV90ASS.SLDASM/meshes/Joint_06_Link.STL" />
      </geometry>
      <material
        name="">
        <color
          rgba="0.749019607843137 0.749019607843137 0.749019607843137 1" />
      </material>
    </visual>
    <collision>
      <origin
        xyz="0 0 0"
        rpy="0 0 0" />
      <geometry>
        <mesh
          filename="package://DRV90ASS.SLDASM/meshes/Joint_06_Link.STL" />
      </geometry>
    </collision>
  </link>
  <joint
    name="Joint06"
    type="revolute">
    <origin
      xyz="0 0 0.074"
      rpy="0 0 0.26255" />
    <parent
      link="Joint05_Link" />
    <child
      link="Joint06_Link" />
    <axis
      xyz="0 0 1" />
    <limit
      lower="-6.2832"
      upper="6.2832"
      effort="9.4"
      velocity="14.312" />
  </joint>
</robot>